<?xml version="1.0" encoding="UTF-8"?>
<!-- Generated by org.testng.reporters.JUnitReportReporter -->
<testsuite skipped="0" hostname="welcome-PC" name="cucumberOptions.TestRunnerTestNG" tests="1" failures="0" timestamp="07 Mar 2019 10:00:58 GMT" time="16.837" errors="1">
  <testcase name="feature" time="16.837" classname="cucumberOptions.TestRunnerTestNG">
    <error type="cucumber.runtime.CucumberException" message="java.lang.AssertionError: The following asserts failed:
	expected [Result for : V12UAA] but found [Sorry record not found]">
      <![CDATA[cucumber.runtime.CucumberException: java.lang.AssertionError: The following asserts failed:
expected [Result for : V12UAA] but found [Sorry record not found]
at cucumber.api.testng.TestNGCucumberRunner.runCucumber(TestNGCucumberRunner.java:69)
at cucumber.api.testng.AbstractTestNGCucumberTests.feature(AbstractTestNGCucumberTests.java:21)
at sun.reflect.NativeMethodAccessorImpl.invoke0(Native Method)
at sun.reflect.NativeMethodAccessorImpl.invoke(NativeMethodAccessorImpl.java:62)
at sun.reflect.DelegatingMethodAccessorImpl.invoke(DelegatingMethodAccessorImpl.java:43)
at java.lang.reflect.Method.invoke(Method.java:498)
at org.testng.internal.MethodInvocationHelper.invokeMethod(MethodInvocationHelper.java:124)
at org.testng.internal.Invoker.invokeMethod(Invoker.java:583)
at org.testng.internal.Invoker.invokeTestMethod(Invoker.java:719)
at org.testng.internal.Invoker.invokeTestMethods(Invoker.java:989)
at org.testng.internal.TestMethodWorker.invokeTestMethods(TestMethodWorker.java:125)
at org.testng.internal.TestMethodWorker.run(TestMethodWorker.java:109)
at org.testng.TestRunner.privateRun(TestRunner.java:648)
at org.testng.TestRunner.run(TestRunner.java:505)
at org.testng.SuiteRunner.runTest(SuiteRunner.java:455)
at org.testng.SuiteRunner.runSequentially(SuiteRunner.java:450)
at org.testng.SuiteRunner.privateRun(SuiteRunner.java:415)
at org.testng.SuiteRunner.run(SuiteRunner.java:364)
at org.testng.SuiteRunnerWorker.runSuite(SuiteRunnerWorker.java:52)
at org.testng.SuiteRunnerWorker.run(SuiteRunnerWorker.java:84)
at org.testng.TestNG.runSuitesSequentially(TestNG.java:1208)
at org.testng.TestNG.runSuitesLocally(TestNG.java:1137)
at org.testng.TestNG.runSuites(TestNG.java:1049)
at org.testng.TestNG.run(TestNG.java:1017)
at org.testng.remote.AbstractRemoteTestNG.run(AbstractRemoteTestNG.java:114)
at org.testng.remote.RemoteTestNG.initAndRun(RemoteTestNG.java:251)
at org.testng.remote.RemoteTestNG.main(RemoteTestNG.java:77)
Caused by: java.lang.AssertionError: The following asserts failed:
expected [Result for : V12UAA] but found [Sorry record not found]
at org.testng.asserts.SoftAssert.assertAll(SoftAssert.java:43)
at resources.Assertion.assert_result(Assertion.java:12)
at insuranceQA_VW.InsuranceCoverTest.validate_the_insurance_cover_start_date_and_end_date(InsuranceCoverTest.java:39)
at âœ½.Then Validate the Insurance cover Start date and End Date(InsuranceCover.feature:7)
]]>
    </error>
  </testcase> <!-- feature -->
</testsuite> <!-- cucumberOptions.TestRunnerTestNG -->
